{"uid":"4b4757e66a1912dae1a509f688f20b0f","name":"categories","children":[{"name":"Product defects","children":[{"name":"snappi_ixnetwork.exceptions.SnappiIxnException: IxNet - One or more ports were forcefully taken by other user IxNet - The Ixia port is not connected.","children":[{"name":"test_bgp_evpn","uid":"116427d14d1c840c","parentUid":"44e21da4cfd2a026cafb1942b4ac833e","status":"failed","time":{"start":1746512584420,"stop":1746512621144,"duration":36724},"flaky":false,"newFailed":true,"newPassed":false,"newBroken":false,"retriesCount":0,"retriesStatusChange":false,"parameters":[],"tags":[]}],"uid":"44e21da4cfd2a026cafb1942b4ac833e"},{"name":"snappi_ixnetwork.exceptions.SnappiIxnException:   File \"/home/github-runner/actions-runner/_work/snappi-ixnetwork/snappi-ixnetwork/snappi_ixnetwork/snappi_api.py\", line 276, in set_config\n    self.config_ixnetwork(config)\n  File \"/home/github-runner/actions-runner/_work/snappi-ixnetwork/snappi-ixnetwork/snappi_ixnetwork/snappi_api.py\", line 360, in config_ixnetwork\n    self.vport.config()\n  File \"/home/github-runner/actions-runner/_work/snappi-ixnetwork/snappi-ixnetwork/snappi_ixnetwork/vport.py\", line 162, in config\n    self._set_location()\n  File \"/home/github-runner/actions-runner/_work/snappi-ixnetwork/snappi-ixnetwork/snappi_ixnetwork/vport.py\", line 368, in _set_location\n    self._api._vport.ConnectPorts()\n  File \"/home/github-runner/actions-runner/_work/snappi-ixnetwork/snappi-ixnetwork/.env/lib/python3.10/site-packages/ixnetwork_restpy/testplatform/sessions/ixnetwork/vport/vport.py\", line 1304, in ConnectPorts\n    return self._execute(\"connectPorts\", payload=payload, response_object=None)\n  File \"/home/github-runner/actions-runner/_work/snappi-ixnetwork/snappi-ixnetwork/.env/lib/python3.10/site-packages/ixnetwork_restpy/base.py\", line 452, in _execute\n    response = self._connection._execute(url, payload)\n  File \"/home/github-runner/actions-runner/_work/snappi-ixnetwork/snappi-ixnetwork/.env/lib/python3.10/site-packages/ixnetwork_restpy/connection.py\", line 289, in _execute\n    return self._send_recv(\"POST\", url, payload)\n  File \"/home/github-runner/actions-runner/_work/snappi-ixnetwork/snappi-ixnetwork/.env/lib/python3.10/site-packages/ixnetwork_restpy/connection.py\", line 572, in _send_recv\n    return self._poll()\n  File \"/home/github-runner/actions-runner/_work/snappi-ixnetwork/snappi-ixnetwork/.env/lib/python3.10/site-packages/ixnetwork_restpy/connection.py\", line 640, in _poll\n    return self._process_response_status_code(\n  File \"/home/github-runner/actions-runner/_work/snappi-ixnetwork/snappi-ixnetwork/.env/lib/python3.10/site-packages/ixnetwork_restpy/connection.py\", line 476, in _process_response_status_code\n    raise BadRequestError(message, response.status_code)\n  Port is in use by other user.","children":[{"name":"test_combined_filters","uid":"2a34906766fd81fc","parentUid":"6c4c292cdfc5ed978dd9dbff6dfeb744","status":"failed","time":{"start":1746512584420,"stop":1746512596801,"duration":12381},"flaky":false,"newFailed":true,"newPassed":false,"newBroken":false,"retriesCount":0,"retriesStatusChange":false,"parameters":[],"tags":[]},{"name":"test_bgp_evpn_validation","uid":"41c212c847374b04","parentUid":"6c4c292cdfc5ed978dd9dbff6dfeb744","status":"failed","time":{"start":1746512584420,"stop":1746512588396,"duration":3976},"flaky":false,"newFailed":true,"newPassed":false,"newBroken":false,"retriesCount":0,"retriesStatusChange":false,"parameters":[],"tags":[]},{"name":"test_bgpv6_evpn_validation","uid":"bcb20792a9879ca0","parentUid":"6c4c292cdfc5ed978dd9dbff6dfeb744","status":"failed","time":{"start":1746512584420,"stop":1746512586948,"duration":2528},"flaky":false,"newFailed":true,"newPassed":false,"newBroken":false,"retriesCount":0,"retriesStatusChange":false,"parameters":[],"tags":[]}],"uid":"6c4c292cdfc5ed978dd9dbff6dfeb744"},{"name":"snappi_ixnetwork.exceptions.SnappiIxnException:   File \"/home/github-runner/actions-runner/_work/snappi-ixnetwork/snappi-ixnetwork/snappi_ixnetwork/snappi_api.py\", line 566, in get_metrics\n    response = self.traffic_item.results_egress_only_tracking(request.egress_only_tracking)\n  File \"/home/github-runner/actions-runner/_work/snappi-ixnetwork/snappi-ixnetwork/snappi_ixnetwork/trafficitem.py\", line 1829, in results_egress_only_tracking\n    ).Page\n  File \"/home/github-runner/actions-runner/_work/snappi-ixnetwork/snappi-ixnetwork/.env/lib/python3.10/site-packages/ixnetwork_restpy/testplatform/sessions/ixnetwork/statistics/view/view.py\", line 554, in Page\n    return Page(self)._select()\n  File \"/home/github-runner/actions-runner/_work/snappi-ixnetwork/snappi-ixnetwork/.env/lib/python3.10/site-packages/ixnetwork_restpy/base.py\", line 548, in _select\n    end = len(self._parent.href)\n  File \"/home/github-runner/actions-runner/_work/snappi-ixnetwork/snappi-ixnetwork/.env/lib/python3.10/site-packages/ixnetwork_restpy/base.py\", line 158, in href\n    return self._get_attribute(\"href\")\n  File \"/home/github-runner/actions-runner/_work/snappi-ixnetwork/snappi-ixnetwork/.env/lib/python3.10/site-packages/ixnetwork_restpy/base.py\", line 218, in _get_attribute\n    raise NotFoundError(msg)\n Failed to get the View.href property as the View object has no encapsulated resources. Either the View.find() method was not called or it failed to retrieve any resources from the server.","children":[{"name":"test_encrypt_with_mka","uid":"cf833875f8a9b6cb","parentUid":"231593e37bacc83b4e142b588efd5552","status":"failed","time":{"start":1746512584420,"stop":1746512706097,"duration":121677},"flaky":true,"newFailed":true,"newPassed":false,"newBroken":false,"retriesCount":0,"retriesStatusChange":false,"parameters":[],"tags":[]}],"uid":"231593e37bacc83b4e142b588efd5552"},{"name":"assert 4 == 2\n +  where 4 = len(<snappi.snappi.Bgpv4MetricIter object at 0x7fdf1c4c88c0>)\n +    where <snappi.snappi.Bgpv4MetricIter object at 0x7fdf1c4c88c0> = <snappi.snappi.MetricsResponse object at 0x7fdf1f49ba60>.bgpv4_metrics","children":[{"name":"test_bgpv4_stats","uid":"22378a07988ab928","parentUid":"604162615c761fdf3046bc071dd5b54e","status":"failed","time":{"start":1746512584420,"stop":1746512666333,"duration":81913},"flaky":false,"newFailed":true,"newPassed":false,"newBroken":false,"retriesCount":0,"retriesStatusChange":false,"parameters":[],"tags":[]}],"uid":"604162615c761fdf3046bc071dd5b54e"},{"name":"snappi_ixnetwork.exceptions.SnappiIxnException:   File \"/home/github-runner/actions-runner/_work/snappi-ixnetwork/snappi-ixnetwork/snappi_ixnetwork/snappi_api.py\", line 450, in set_control_state\n    self.traffic_item.transmit(request_payload)\n  File \"/home/github-runner/actions-runner/_work/snappi-ixnetwork/snappi-ixnetwork/snappi_ixnetwork/trafficitem.py\", line 1484, in transmit\n    self._api._traffic.Apply()\n  File \"/home/github-runner/actions-runner/_work/snappi-ixnetwork/snappi-ixnetwork/.env/lib/python3.10/site-packages/ixnetwork_restpy/testplatform/sessions/ixnetwork/traffic/traffic.py\", line 1395, in Apply\n    return self._execute(\"apply\", payload=payload, response_object=None)\n  File \"/home/github-runner/actions-runner/_work/snappi-ixnetwork/snappi-ixnetwork/.env/lib/python3.10/site-packages/ixnetwork_restpy/base.py\", line 452, in _execute\n    response = self._connection._execute(url, payload)\n  File \"/home/github-runner/actions-runner/_work/snappi-ixnetwork/snappi-ixnetwork/.env/lib/python3.10/site-packages/ixnetwork_restpy/connection.py\", line 289, in _execute\n    return self._send_recv(\"POST\", url, payload)\n  File \"/home/github-runner/actions-runner/_work/snappi-ixnetwork/snappi-ixnetwork/.env/lib/python3.10/site-packages/ixnetwork_restpy/connection.py\", line 572, in _send_recv\n    return self._poll()\n  File \"/home/github-runner/actions-runner/_work/snappi-ixnetwork/snappi-ixnetwork/.env/lib/python3.10/site-packages/ixnetwork_restpy/connection.py\", line 640, in _poll\n    return self._process_response_status_code(\n  File \"/home/github-runner/actions-runner/_work/snappi-ixnetwork/snappi-ixnetwork/.env/lib/python3.10/site-packages/ixnetwork_restpy/connection.py\", line 476, in _process_response_status_code\n    raise BadRequestError(message, response.status_code)\n  Error in L2/L3 Traffic Apply","children":[{"name":"test_encrypt_with_mka_multiple_devices","uid":"f5b2faef908c04fb","parentUid":"2049ebdf5f089aa39cac93c0c8e5e6e4","status":"failed","time":{"start":1746512584420,"stop":1746512660100,"duration":75680},"flaky":true,"newFailed":true,"newPassed":false,"newBroken":false,"retriesCount":0,"retriesStatusChange":false,"parameters":[],"tags":[]}],"uid":"2049ebdf5f089aa39cac93c0c8e5e6e4"},{"name":"snappi_ixnetwork.exceptions.SnappiIxnException:   File \"/home/github-runner/actions-runner/_work/snappi-ixnetwork/snappi-ixnetwork/snappi_ixnetwork/snappi_api.py\", line 446, in set_control_state\n    event_names = self.ngpf.set_route_state(request_payload)\n  File \"/home/github-runner/actions-runner/_work/snappi-ixnetwork/snappi-ixnetwork/snappi_ixnetwork/device/ngpf.py\", line 313, in set_route_state\n    self.api._ixnetwork.Globals.Topology.ApplyOnTheFly()\n  File \"/home/github-runner/actions-runner/_work/snappi-ixnetwork/snappi-ixnetwork/.env/lib/python3.10/site-packages/ixnetwork_restpy/testplatform/sessions/ixnetwork/globals/topology/topology_678a8dc80c9b4b2b5c741072eab4305d.py\", line 1846, in ApplyOnTheFly\n    return self._execute(\"applyOnTheFly\", payload=payload, response_object=None)\n  File \"/home/github-runner/actions-runner/_work/snappi-ixnetwork/snappi-ixnetwork/.env/lib/python3.10/site-packages/ixnetwork_restpy/base.py\", line 452, in _execute\n    response = self._connection._execute(url, payload)\n  File \"/home/github-runner/actions-runner/_work/snappi-ixnetwork/snappi-ixnetwork/.env/lib/python3.10/site-packages/ixnetwork_restpy/connection.py\", line 289, in _execute\n    return self._send_recv(\"POST\", url, payload)\n  File \"/home/github-runner/actions-runner/_work/snappi-ixnetwork/snappi-ixnetwork/.env/lib/python3.10/site-packages/ixnetwork_restpy/connection.py\", line 572, in _send_recv\n    return self._poll()\n  File \"/home/github-runner/actions-runner/_work/snappi-ixnetwork/snappi-ixnetwork/.env/lib/python3.10/site-packages/ixnetwork_restpy/connection.py\", line 640, in _poll\n    return self._process_response_status_code(\n  File \"/home/github-runner/actions-runner/_work/snappi-ixnetwork/snappi-ixnetwork/.env/lib/python3.10/site-packages/ixnetwork_restpy/connection.py\", line 476, in _process_response_status_code\n    raise BadRequestError(message, response.status_code)\n  Action ApplyChanges cannot be executed while other actions are in progress. Actions in progress: \nClear Stats Rx Bgp 1\n.","children":[{"name":"test_compact","uid":"5dbefb720656cb34","parentUid":"505fed93f14264f3f5b1376cd8b07ed1","status":"failed","time":{"start":1746512584420,"stop":1746512671201,"duration":86781},"flaky":true,"newFailed":true,"newPassed":false,"newBroken":false,"retriesCount":0,"retriesStatusChange":false,"parameters":[],"tags":[]}],"uid":"505fed93f14264f3f5b1376cd8b07ed1"},{"name":"snappi_ixnetwork.exceptions.SnappiIxnException:   File \"/home/github-runner/actions-runner/_work/snappi-ixnetwork/snappi-ixnetwork/snappi_ixnetwork/snappi_api.py\", line 276, in set_config\n    self.config_ixnetwork(config)\n  File \"/home/github-runner/actions-runner/_work/snappi-ixnetwork/snappi-ixnetwork/snappi_ixnetwork/snappi_api.py\", line 363, in config_ixnetwork\n    self.ngpf.config()\n  File \"/home/github-runner/actions-runner/_work/snappi-ixnetwork/snappi-ixnetwork/snappi_ixnetwork/device/ngpf.py\", line 69, in config\n    self._configure_topology()\n  File \"/home/github-runner/actions-runner/_work/snappi-ixnetwork/snappi-ixnetwork/snappi_ixnetwork/device/ngpf.py\", line 110, in _configure_topology\n    self.api._remove(self.api._topology, [])\n  File \"/home/github-runner/actions-runner/_work/snappi-ixnetwork/snappi-ixnetwork/snappi_ixnetwork/snappi_api.py\", line 1163, in _remove\n    ixn_obj.remove()\n  File \"/home/github-runner/actions-runner/_work/snappi-ixnetwork/snappi-ixnetwork/.env/lib/python3.10/site-packages/ixnetwork_restpy/testplatform/sessions/ixnetwork/topology/topology_9d0fe0bb2c064aa7010adbdb6cf68958.py\", line 250, in remove\n    self._delete()\n  File \"/home/github-runner/actions-runner/_work/snappi-ixnetwork/snappi-ixnetwork/.env/lib/python3.10/site-packages/ixnetwork_restpy/base.py\", line 441, in _delete\n    raise e\n  File \"/home/github-runner/actions-runner/_work/snappi-ixnetwork/snappi-ixnetwork/.env/lib/python3.10/site-packages/ixnetwork_restpy/base.py\", line 438, in _delete\n    self._connection._delete(url)\n  File \"/home/github-runner/actions-runner/_work/snappi-ixnetwork/snappi-ixnetwork/.env/lib/python3.10/site-packages/ixnetwork_restpy/connection.py\", line 286, in _delete\n    return self._send_recv(\"DELETE\", url, payload)\n  File \"/home/github-runner/actions-runner/_work/snappi-ixnetwork/snappi-ixnetwork/.env/lib/python3.10/site-packages/ixnetwork_restpy/connection.py\", line 596, in _send_recv\n    self._process_response_status_code(url, headers, response)\n  File \"/home/github-runner/actions-runner/_work/snappi-ixnetwork/snappi-ixnetwork/.env/lib/python3.10/site-packages/ixnetwork_restpy/connection.py\", line 476, in _process_response_status_code\n    raise BadRequestError(message, response.status_code)\n Unable to delete /topology:2 Topology rx: Removing a Topology from a started Topology is not permitted.\n\tCurrent Server Errors/Warnings:\n\t05/06/2025 18:46:32 [WARNING] [Protocols Version Mismatch] Protocols Version Mismatch.\nIxNetwork Protocols Version: 10.80.2412.12\nChassis Protocols Version: 10.50.2410.2\n\t05/06/2025 18:50:29 [ERROR] [Topology rx: Removing a Topology from a started Topology is not permitted.] \n\t05/06/2025 18:50:29 [WARNING] [Note that your changes are pending to be applied after the following action(s) and any of their sequels complete:\nClear Stats edge_bgp2, \nStopping edge_bgp2, \n] \n\t05/06/2025 18:45:53 [WARNING] [Traffic Generate required] The Traffic Item was modified. Please perform a Traffic Generate to update the associated traffic Flow Groups\n\t05/06/2025 18:50:25 [WARNING] [Regenerate Traffic Item Required] The Traffic Item configuration has changed and it needs to be regenerated before applying it to the Ixia hardware\n\t05/06/2025 18:49:51 [WARNING] [Frames Size Adjusted] The frame size was increased to 156 bytes to accommodate encapsulation requirements.  - The frame size was adjusted to conform to the encapsulation requirements","children":[{"name":"test_vxlan_compact","uid":"2924c751ea49754c","parentUid":"ce7873caa7cf2c185b88091f2ec4859b","status":"failed","time":{"start":1746512584420,"stop":1746512589390,"duration":4970},"flaky":false,"newFailed":true,"newPassed":false,"newBroken":false,"retriesCount":0,"retriesStatusChange":false,"parameters":[],"tags":[]}],"uid":"ce7873caa7cf2c185b88091f2ec4859b"}],"uid":"8fb3a91ba5aaf9de24cc8a92edc82b5d"}]}