{"uid":"4b4757e66a1912dae1a509f688f20b0f","name":"categories","children":[{"name":"Product defects","children":[{"name":"snappi_ixnetwork.exceptions.SnappiIxnException:   File \"/home/github-runner/actions-runner/_work/snappi-ixnetwork/snappi-ixnetwork/snappi_ixnetwork/snappi_api.py\", line 276, in set_config\n    self.config_ixnetwork(config)\n  File \"/home/github-runner/actions-runner/_work/snappi-ixnetwork/snappi-ixnetwork/snappi_ixnetwork/snappi_api.py\", line 374, in config_ixnetwork\n    self._ixnetwork.StartAllProtocols()\n  File \"/home/github-runner/actions-runner/_work/snappi-ixnetwork/snappi-ixnetwork/.env/lib/python3.10/site-packages/ixnetwork_restpy/testplatform/sessions/ixnetwork/ixnetwork.py\", line 2862, in StartAllProtocols\n    return self._execute(\"startAllProtocols\", payload=payload, response_object=None)\n  File \"/home/github-runner/actions-runner/_work/snappi-ixnetwork/snappi-ixnetwork/.env/lib/python3.10/site-packages/ixnetwork_restpy/base.py\", line 452, in _execute\n    response = self._connection._execute(url, payload)\n  File \"/home/github-runner/actions-runner/_work/snappi-ixnetwork/snappi-ixnetwork/.env/lib/python3.10/site-packages/ixnetwork_restpy/connection.py\", line 289, in _execute\n    return self._send_recv(\"POST\", url, payload)\n  File \"/home/github-runner/actions-runner/_work/snappi-ixnetwork/snappi-ixnetwork/.env/lib/python3.10/site-packages/ixnetwork_restpy/connection.py\", line 572, in _send_recv\n    return self._poll()\n  File \"/home/github-runner/actions-runner/_work/snappi-ixnetwork/snappi-ixnetwork/.env/lib/python3.10/site-packages/ixnetwork_restpy/connection.py\", line 640, in _poll\n    return self._process_response_status_code(\n  File \"/home/github-runner/actions-runner/_work/snappi-ixnetwork/snappi-ixnetwork/.env/lib/python3.10/site-packages/ixnetwork_restpy/connection.py\", line 476, in _process_response_status_code\n    raise BadRequestError(message, response.status_code)\n  No ports assigned to the Port Group: p1\nThe Ixia port is not connected.\nSystem Exception Caught. Exception Text: The Ixia port is not connected.","children":[{"name":"test_device_lag_name","uid":"95eec0d50bf1f0d6","parentUid":"3bd7fff3e580b4994b2c53d7053bfdc0","status":"failed","time":{"start":1745937122343,"stop":1745937171851,"duration":49508},"flaky":false,"newFailed":true,"newPassed":false,"newBroken":false,"retriesCount":0,"retriesStatusChange":false,"parameters":[],"tags":[]}],"uid":"3bd7fff3e580b4994b2c53d7053bfdc0"},{"name":"snappi_ixnetwork.exceptions.SnappiIxnException:   File \"/home/github-runner/actions-runner/_work/snappi-ixnetwork/snappi-ixnetwork/snappi_ixnetwork/snappi_api.py\", line 276, in set_config\n    self.config_ixnetwork(config)\n  File \"/home/github-runner/actions-runner/_work/snappi-ixnetwork/snappi-ixnetwork/snappi_ixnetwork/snappi_api.py\", line 360, in config_ixnetwork\n    self.vport.config()\n  File \"/home/github-runner/actions-runner/_work/snappi-ixnetwork/snappi-ixnetwork/snappi_ixnetwork/vport.py\", line 162, in config\n    self._set_location()\n  File \"/home/github-runner/actions-runner/_work/snappi-ixnetwork/snappi-ixnetwork/snappi_ixnetwork/vport.py\", line 368, in _set_location\n    self._api._vport.ConnectPorts()\n  File \"/home/github-runner/actions-runner/_work/snappi-ixnetwork/snappi-ixnetwork/.env/lib/python3.10/site-packages/ixnetwork_restpy/testplatform/sessions/ixnetwork/vport/vport.py\", line 1304, in ConnectPorts\n    return self._execute(\"connectPorts\", payload=payload, response_object=None)\n  File \"/home/github-runner/actions-runner/_work/snappi-ixnetwork/snappi-ixnetwork/.env/lib/python3.10/site-packages/ixnetwork_restpy/base.py\", line 452, in _execute\n    response = self._connection._execute(url, payload)\n  File \"/home/github-runner/actions-runner/_work/snappi-ixnetwork/snappi-ixnetwork/.env/lib/python3.10/site-packages/ixnetwork_restpy/connection.py\", line 289, in _execute\n    return self._send_recv(\"POST\", url, payload)\n  File \"/home/github-runner/actions-runner/_work/snappi-ixnetwork/snappi-ixnetwork/.env/lib/python3.10/site-packages/ixnetwork_restpy/connection.py\", line 572, in _send_recv\n    return self._poll()\n  File \"/home/github-runner/actions-runner/_work/snappi-ixnetwork/snappi-ixnetwork/.env/lib/python3.10/site-packages/ixnetwork_restpy/connection.py\", line 640, in _poll\n    return self._process_response_status_code(\n  File \"/home/github-runner/actions-runner/_work/snappi-ixnetwork/snappi-ixnetwork/.env/lib/python3.10/site-packages/ixnetwork_restpy/connection.py\", line 476, in _process_response_status_code\n    raise BadRequestError(message, response.status_code)\n  Port is in use by other user.","children":[{"name":"test_port_name","uid":"82c3576b21a7b735","parentUid":"6c4c292cdfc5ed978dd9dbff6dfeb744","status":"failed","time":{"start":1745937122343,"stop":1745937126726,"duration":4383},"flaky":false,"newFailed":true,"newPassed":false,"newBroken":false,"retriesCount":0,"retriesStatusChange":false,"parameters":[],"tags":[]}],"uid":"6c4c292cdfc5ed978dd9dbff6dfeb744"},{"name":"assert 0 == 1\n +  where 0 = len(<ixnetwork_restpy.testplatform.sessions.ixnetwork.availablehardware.chassis.chassis.Chassis object at 0x7f8968e290c0>)","children":[{"name":"test_counter_ip_dscp","uid":"edac40c16e1b6a83","parentUid":"8d2b2b53b6dbf800915cb5ab97ab7be6","status":"failed","time":{"start":1745937122343,"stop":1745937142105,"duration":19762},"flaky":false,"newFailed":false,"newPassed":false,"newBroken":false,"retriesCount":0,"retriesStatusChange":false,"parameters":[],"tags":[]}],"uid":"8d2b2b53b6dbf800915cb5ab97ab7be6"}],"uid":"8fb3a91ba5aaf9de24cc8a92edc82b5d"}]}